Workbook

Sheet Sheet1
A1: original data | P1: m002 UTR, benchmark
A2: P1
B3: <> | C3: 1 | D3: 2 | E3: 3 | F3: 4 | G3: 5 | H3: 6 | I3: 7 | J3: 8 | K3: 9 | L3: 10 | M3: 11 | N3: 12
B4: A | C4: 1.1351 | D4: 0.7235 | E4: 0.6943 | F4: 0.6305 | G4: 0.5401 | H4: 0.5068 | I4: 0.5708 | J4: 0.5292 | K4: 0.5877 | L4: 0.5502 | M4: 0.5987 | N4: 0.659
B5: B | C5: 0.5334 | D5: 0.5216 | E5: 0.5356 | F5: 0.4519 | G5: 0.4262 | H5: 0.4231 | I5: 0.4279 | J5: 0.4199 | K5: 0.5062 | L5: 0.4868 | M5: 0.4753 | N5: 0.5092
B6: C | C6: 0.549 | D6: 0.4355 | E6: 0.4688 | F6: 0.416 | G6: 0.4592 | H6: 0.4294 | I6: 0.4402 | J6: 0.4277 | K6: 0.5557 | L6: 0.4875 | M6: 0.4707 | N6: 0.5476
B7: D | C7: 0.521 | D7: 0.4705 | E7: 0.4339 | F7: 0.4468 | G7: 0.4733 | H7: 0.4002 | I7: 0.4169 | J7: 0.5047 | K7: 0.4381 | L7: 0.4947 | M7: 0.5809 | N7: 0.5461
B8: E | C8: 0.5044 | D8: 0.5807 | E8: 0.4663 | F8: 0.4299 | G8: 0.4536 | H8: 0.4429 | I8: 0.5193 | J8: 0.5638 | K8: 0.4619 | L8: 0.5107 | M8: 0.5215 | N8: 1.217
B9: F | C9: 0.5104 | D9: 0.5596 | E9: 0.4822 | F9: 0.4445 | G9: 0.5304 | H9: 0.4333 | I9: 0.5303 | J9: 0.5759 | K9: 0.5474 | L9: 0.4944 | M9: 0.6409 | N9: 1.0162
B10: G | C10: 0.4867 | D10: 0.5244 | E10: 0.5437 | F10: 0.573 | G10: 0.4508 | H10: 0.55 | I10: 0.6682 | J10: 0.5943 | K10: 0.6304 | L10: 0.5675 | M10: 0.6315 | N10: 1.2858
B11: H | C11: 0.5811 | D11: 0.6146 | E11: 0.5839 | F11: 0.6385 | G11: 0.6224 | H11: 0.5758 | I11: 0.5952 | J11: 4.1 | K11: 0.5403 | L11: 0.6009 | M11: 0.6011 | N11: 1.1861
A13: P2
B14: <> | C14: 1 | D14: 2 | E14: 3 | F14: 4 | G14: 5 | H14: 6 | I14: 7 | J14: 8 | K14: 9 | L14: 10 | M14: 11 | N14: 12
B15: A | C15: 1.011 | D15: 0.6064 | E15: 0.5509 | F15: 0.5811 | G15: 0.4625 | H15: 0.4401 | I15: 0.472 | J15: 0.4995 | K15: 0.5143 | L15: 0.4694 | M15: 0.4851 | N15: 0.5454
B16: B | C16: 0.4655 | D16: 0.3921 | E16: 0.3831 | F16: 0.3617 | G16: 0.3094 | H16: 0.3461 | I16: 0.2597 | J16: 0.3092 | K16: 0.3143 | L16: 0.3529 | M16: 0.9004 | N16: 0.4219
B17: C | C17: 0.5127 | D17: 0.4012 | E17: 0.3146 | F17: 0.3194 | G17: 0.3479 | H17: 0.289 | I17: 0.2778 | J17: 0.3051 | K17: 0.3787 | L17: 0.3023 | M17: 0.3267 | N17: 0.4784
B18: D | C18: 0.3448 | D18: 0.344 | E18: 0.305 | F18: 0.3569 | G18: 0.2682 | H18: 0.2672 | I18: 0.33 | J18: 0.3496 | K18: 0.322 | L18: 0.4335 | M18: 0.317 | N18: 0.4046
B19: E | C19: 0.4624 | D19: 0.3687 | E19: 0.3458 | F19: 0.3157 | G19: 0.3246 | H19: 0.2919 | I19: 0.3311 | J19: 0.4264 | K19: 0.3668 | L19: 0.3952 | M19: 0.3169 | N19: 1.2403
B20: F | C20: 0.4604 | D20: 0.3787 | E20: 0.3403 | F20: 0.3326 | G20: 0.3168 | H20: 0.2815 | I20: 0.3623 | J20: 0.3998 | K20: 0.3879 | L20: 0.4292 | M20: 0.4342 | N20: 1.0205
B21: G | C21: 0.396 | D21: 0.368 | E21: 0.3902 | F21: 0.4499 | G21: 0.412 | H21: 0.4226 | I21: 0.3981 | J21: 0.412 | K21: 0.4478 | L21: 0.5003 | M21: 0.4125 | N21: 0.8136
B22: H | C22: 0.5188 | D22: 0.4487 | E22: 0.4442 | F22: 0.4549 | G22: 0.4076 | H22: 0.4954 | I22: 0.4272 | J22: 4.004 | K22: 0.467 | L22: 0.4091 | M22: 0.545 | N22: 0.7976
A24: P3
B25: <> | C25: 1 | D25: 2 | E25: 3 | F25: 4 | G25: 5 | H25: 6 | I25: 7 | J25: 8 | K25: 9 | L25: 10 | M25: 11 | N25: 12
B26: A | C26: 1.2392 | D26: 0.9093 | E26: 0.7074 | F26: 0.7188 | G26: 0.5473 | H26: 0.5804 | I26: 0.5064 | J26: 0.4635 | K26: 0.4995 | L26: 0.4768 | M26: 0.4172 | N26: 0.5298
B27: B | C27: 0.5655 | D27: 0.5832 | E27: 0.522 | F27: 0.5139 | G27: 0.4551 | H27: 0.3788 | I27: 0.3279 | J27: 0.3144 | K27: 0.3875 | L27: 0.3639 | M27: 0.3649 | N27: 0.4691
B28: C | C28: 0.4684 | D28: 0.4589 | E28: 0.4582 | F28: 0.3901 | G28: 0.3294 | H28: 0.3104 | I28: 0.3165 | J28: 0.3304 | K28: 0.3902 | L28: 0.4227 | M28: 0.3317 | N28: 0.4986
B29: D | C29: 0.5117 | D29: 0.5118 | E29: 0.4824 | F29: 0.4215 | G29: 0.3922 | H29: 0.3949 | I29: 0.3373 | J29: 0.3735 | K29: 0.3868 | L29: 0.4027 | M29: 0.3654 | N29: 0.5232
B30: E | C30: 0.5381 | D30: 0.4757 | E30: 0.4745 | F30: 0.3312 | G30: 0.3496 | H30: 0.453 | I30: 0.3385 | J30: 0.4212 | K30: 0.3909 | L30: 0.3965 | M30: 0.4159 | N30: 1.0922
B31: F | C31: 0.6265 | D31: 0.517 | E31: 0.548 | F31: 0.3932 | G31: 0.3566 | H31: 0.4135 | I31: 0.4156 | J31: 0.5032 | K31: 0.3532 | L31: 0.3858 | M31: 0.4892 | N31: 1.5358
B32: G | C32: 0.624 | D32: 0.4631 | E32: 0.499 | F32: 0.4286 | G32: 0.448 | H32: 0.4303 | I32: 0.4043 | J32: 0.3632 | K32: 0.3899 | L32: 0.3571 | M32: 0.4829 | N32: 1.1191
B33: H | C33: 0.5252 | D33: 0.5427 | E33: 0.592 | F33: 0.4943 | G33: 0.4654 | H33: 0.4515 | I33: 0.4174 | J33: 4.159 | K33: 0.4083 | L33: 0.4098 | M33: 0.4498 | N33: 1.1218
A35: P4
B36: <> | C36: 1 | D36: 2 | E36: 3 | F36: 4 | G36: 5 | H36: 6 | I36: 7 | J36: 8 | K36: 9 | L36: 10 | M36: 11 | N36: 12
B37: A | C37: 1.2712 | D37: 0.625 | E37: 0.5325 | F37: 0.4402 | G37: 0.4591 | H37: 0.4314 | I37: 0.4285 | J37: 0.4804 | K37: 0.4525 | L37: 0.4762 | M37: 0.3725 | N37: 0.5004
B38: B | C38: 0.4977 | D38: 0.4822 | E38: 0.3595 | F38: 0.323 | G38: 0.2427 | H38: 0.2789 | I38: 0.3131 | J38: 0.2911 | K38: 0.2507 | L38: 0.2818 | M38: 0.2779 | N38: 0.3779
B39: C | C39: 0.5298 | D39: 0.354 | E39: 0.3813 | F39: 0.2737 | G39: 0.2586 | H39: 0.3109 | I39: 0.2263 | J39: 0.2586 | K39: 0.315 | L39: 0.2815 | M39: 0.3223 | N39: 0.4115
B40: D | C40: 0.5323 | D40: 0.4024 | E40: 0.2547 | F40: 0.3561 | G40: 0.2896 | H40: 0.2465 | I40: 0.2216 | J40: 0.293 | K40: 0.259 | L40: 0.3027 | M40: 0.3133 | N40: 0.4201
B41: E | C41: 0.5051 | D41: 0.4133 | E41: 0.2961 | F41: 0.2672 | G41: 0.3557 | H41: 0.259 | I41: 0.2971 | J41: 0.2769 | K41: 0.3015 | L41: 0.3353 | M41: 0.3252 | N41: 0.8583
B42: F | C42: 0.5396 | D42: 0.338 | E42: 0.2991 | F42: 0.3182 | G42: 0.3493 | H42: 0.3072 | I42: 0.3251 | J42: 0.37 | K42: 0.3655 | L42: 0.3467 | M42: 0.3818 | N42: 0.8129
B43: G | C43: 0.5647 | D43: 0.3657 | E43: 0.355 | F43: 0.4449 | G43: 0.2905 | H43: 0.3087 | I43: 0.3165 | J43: 0.3008 | K43: 0.3482 | L43: 0.3699 | M43: 0.4477 | N43: 0.5593
...

Sheet Sheet2
A1: fold change to m002 benchmark | P1: m002 UTR, benchmark
A2: P1
B3: <> | C3: 1 | D3: 2 | E3: 3 | F3: 4 | G3: 5 | H3: 6 | I3: 7 | J3: 8 | K3: 9 | L3: 10 | M3: 11 | N3: 12
B4: A | C4: =Sheet1!C4/Sheet1!$N7 -> 2.078557 | D4: =Sheet1!D4/Sheet1!$N7 -> 1.3248489 | E4: =Sheet1!E4/Sheet1!$N7 -> 1.2713789 | F4: =Sheet1!F4/Sheet1!$N7 -> 1.1545504 | G4: =Sheet1!G4/Sheet1!$N7 -> 0.989013 | H4: =Sheet1!H4/Sheet1!$N7 -> 0.92803516 | I4: =Sheet1!I4/Sheet1!$N7 -> 1.0452298 | J4: =Sheet1!J4/Sheet1!$N7 -> 0.96905329 | ... N4: =Sheet1!N4/Sheet1!$N7 -> 1.2067387
B5: B | C5: =Sheet1!C5/Sheet1!$N7 -> 0.97674419 | D5: =Sheet1!D5/Sheet1!$N7 -> 0.95513642 | E5: =Sheet1!E5/Sheet1!$N7 -> 0.98077275 | F5: =Sheet1!F5/Sheet1!$N7 -> 0.82750412 | G5: =Sheet1!G5/Sheet1!$N7 -> 0.78044314 | H5: =Sheet1!H5/Sheet1!$N7 -> 0.77476653 | I5: =Sheet1!I5/Sheet1!$N7 -> 0.78355613 | J5: =Sheet1!J5/Sheet1!$N7 -> 0.76890679 | ... N5: =Sheet1!N5/Sheet1!$N7 -> 0.93242996
B6: C | C6: =Sheet1!C6/Sheet1!$N7 -> 1.0053104 | D6: =Sheet1!D6/Sheet1!$N7 -> 0.79747299 | E6: =Sheet1!E6/Sheet1!$N7 -> 0.85845083 | F6: =Sheet1!F6/Sheet1!$N7 -> 0.76176524 | G6: =Sheet1!G6/Sheet1!$N7 -> 0.84087164 | H6: =Sheet1!H6/Sheet1!$N7 -> 0.78630287 | I6: =Sheet1!I6/Sheet1!$N7 -> 0.80607947 | J6: =Sheet1!J6/Sheet1!$N7 -> 0.78318989 | ... N6: =Sheet1!N6/Sheet1!$N7 -> 1.0027467
B7: D | C7: =Sheet1!C7/Sheet1!$N7 -> 0.95403772 | D7: =Sheet1!D7/Sheet1!$N7 -> 0.86156382 | E7: =Sheet1!E7/Sheet1!$N7 -> 0.79454312 | F7: =Sheet1!F7/Sheet1!$N7 -> 0.81816517 | G7: =Sheet1!G7/Sheet1!$N7 -> 0.86669108 | H7: =Sheet1!H7/Sheet1!$N7 -> 0.73283281 | I7: =Sheet1!I7/Sheet1!$N7 -> 0.76341329 | J7: =Sheet1!J7/Sheet1!$N7 -> 0.92418971 | ... N7: =Sheet1!N7/Sheet1!$N7 -> 1
B8: E | C8: =Sheet1!C8/Sheet1!$N7 -> 0.92364036 | D8: =Sheet1!D8/Sheet1!$N7 -> 1.0633584 | E8: =Sheet1!E8/Sheet1!$N7 -> 0.85387292 | F8: =Sheet1!F8/Sheet1!$N7 -> 0.78721846 | G8: =Sheet1!G8/Sheet1!$N7 -> 0.8306171 | H8: =Sheet1!H8/Sheet1!$N7 -> 0.81102362 | I8: =Sheet1!I8/Sheet1!$N7 -> 0.95092474 | J8: =Sheet1!J8/Sheet1!$N7 -> 1.0324116 | ... N8: =Sheet1!N8/Sheet1!$N7 -> 2.2285296
B9: F | C9: =Sheet1!C9/Sheet1!$N7 -> 0.93462736 | D9: =Sheet1!D9/Sheet1!$N7 -> 1.0247207 | E9: =Sheet1!E9/Sheet1!$N7 -> 0.88298846 | F9: =Sheet1!F9/Sheet1!$N7 -> 0.81395349 | G9: =Sheet1!G9/Sheet1!$N7 -> 0.97125069 | H9: =Sheet1!H9/Sheet1!$N7 -> 0.79344442 | I9: =Sheet1!I9/Sheet1!$N7 -> 0.97106757 | J9: =Sheet1!J9/Sheet1!$N7 -> 1.0545688 | ... N9: =Sheet1!N9/Sheet1!$N7 -> 1.8608313
B10: G | C10: =Sheet1!C10/Sheet1!$N7 -> 0.89122871 | D10: =Sheet1!D10/Sheet1!$N7 -> 0.96026369 | E10: =Sheet1!E10/Sheet1!$N7 -> 0.9956052 | F10: =Sheet1!F10/Sheet1!$N7 -> 1.0492584 | G10: =Sheet1!G10/Sheet1!$N7 -> 0.82548984 | H10: =Sheet1!H10/Sheet1!$N7 -> 1.0071415 | I10: =Sheet1!I10/Sheet1!$N7 -> 1.2235854 | J10: =Sheet1!J10/Sheet1!$N7 -> 1.0882622 | ... N10: =Sheet1!N10/Sheet1!$N7 -> 2.3545138
B11: H | C11: =Sheet1!C11/Sheet1!$N7 -> 1.0640908 | D11: =Sheet1!D11/Sheet1!$N7 -> 1.1254349 | E11: =Sheet1!E11/Sheet1!$N7 -> 1.0692181 | F11: =Sheet1!F11/Sheet1!$N7 -> 1.1691998 | G11: =Sheet1!G11/Sheet1!$N7 -> 1.139718 | H11: =Sheet1!H11/Sheet1!$N7 -> 1.0543856 | I11: =Sheet1!I11/Sheet1!$N7 -> 1.0899103 | J11: =Sheet1!J11/Sheet1!$N7 -> 7.5077825 | ... N11: =Sheet1!N11/Sheet1!$N7 -> 2.1719465
A13: P2
B14: <> | C14: 1 | D14: 2 | E14: 3 | F14: 4 | G14: 5 | H14: 6 | I14: 7 | J14: 8 | K14: 9 | L14: 10 | M14: 11 | N14: 12
B15: A | C15: =Sheet1!C15/Sheet1!$N18 -> 2.4987642 | D15: =Sheet1!D15/Sheet1!$N18 -> 1.4987642 | E15: =Sheet1!E15/Sheet1!$N18 -> 1.3615917 | F15: =Sheet1!F15/Sheet1!$N18 -> 1.4362333 | G15: =Sheet1!G15/Sheet1!$N18 -> 1.1431043 | H15: =Sheet1!H15/Sheet1!$N18 -> 1.087741 | I15: =Sheet1!I15/Sheet1!$N18 -> 1.1665843 | J15: =Sheet1!J15/Sheet1!$N18 -> 1.2345526 | ... N15: =Sheet1!N15/Sheet1!$N18 -> 1.347998
B16: B | C16: =Sheet1!C16/Sheet1!$N18 -> 1.150519 | D16: =Sheet1!D16/Sheet1!$N18 -> 0.96910529 | E16: =Sheet1!E16/Sheet1!$N18 -> 0.9468611 | F16: =Sheet1!F16/Sheet1!$N18 -> 0.89396935 | G16: =Sheet1!G16/Sheet1!$N18 -> 0.76470588 | H16: =Sheet1!H16/Sheet1!$N18 -> 0.85541275 | I16: =Sheet1!I16/Sheet1!$N18 -> 0.64186851 | J16: =Sheet1!J16/Sheet1!$N18 -> 0.76421157 | ... N16: =Sheet1!N16/Sheet1!$N18 -> 1.0427583
B17: C | C17: =Sheet1!C17/Sheet1!$N18 -> 1.2671775 | D17: =Sheet1!D17/Sheet1!$N18 -> 0.99159664 | E17: =Sheet1!E17/Sheet1!$N18 -> 0.77755808 | F17: =Sheet1!F17/Sheet1!$N18 -> 0.78942165 | G17: =Sheet1!G17/Sheet1!$N18 -> 0.85986159 | H17: =Sheet1!H17/Sheet1!$N18 -> 0.71428571 | I17: =Sheet1!I17/Sheet1!$N18 -> 0.68660405 | J17: =Sheet1!J17/Sheet1!$N18 -> 0.7540781 | ... N17: =Sheet1!N17/Sheet1!$N18 -> 1.1824024
B18: D | C18: =Sheet1!C18/Sheet1!$N18 -> 0.8521997 | D18: =Sheet1!D18/Sheet1!$N18 -> 0.85022244 | E18: =Sheet1!E18/Sheet1!$N18 -> 0.75383094 | F18: =Sheet1!F18/Sheet1!$N18 -> 0.88210578 | G18: =Sheet1!G18/Sheet1!$N18 -> 0.66287692 | H18: =Sheet1!H18/Sheet1!$N18 -> 0.66040534 | I18: =Sheet1!I18/Sheet1!$N18 -> 0.81562037 | J18: =Sheet1!J18/Sheet1!$N18 -> 0.86406327 | ... N18: =Sheet1!N18/Sheet1!$N18 -> 1
B19: E | C19: =Sheet1!C19/Sheet1!$N18 -> 1.1428571 | D19: =Sheet1!D19/Sheet1!$N18 -> 0.91127039 | E19: =Sheet1!E19/Sheet1!$N18 -> 0.85467128 | F19: =Sheet1!F19/Sheet1!$N18 -> 0.78027682 | G19: =Sheet1!G19/Sheet1!$N18 -> 0.80227385 | H19: =Sheet1!H19/Sheet1!$N18 -> 0.72145329 | I19: =Sheet1!I19/Sheet1!$N18 -> 0.8183391 | J19: =Sheet1!J19/Sheet1!$N18 -> 1.0538804 | ... N19: =Sheet1!N19/Sheet1!$N18 -> 3.0654968
B20: F | C20: =Sheet1!C20/Sheet1!$N18 -> 1.137914 | D20: =Sheet1!D20/Sheet1!$N18 -> 0.93598616 | E20: =Sheet1!E20/Sheet1!$N18 -> 0.84107761 | F20: =Sheet1!F20/Sheet1!$N18 -> 0.82204647 | G20: =Sheet1!G20/Sheet1!$N18 -> 0.78299555 | H20: =Sheet1!H20/Sheet1!$N18 -> 0.69574889 | I20: =Sheet1!I20/Sheet1!$N18 -> 0.8954523 | J20: =Sheet1!J20/Sheet1!$N18 -> 0.98813643 | ... N20: =Sheet1!N20/Sheet1!$N18 -> 2.5222442
B21: G | C21: =Sheet1!C21/Sheet1!$N18 -> 0.97874444 | D21: =Sheet1!D21/Sheet1!$N18 -> 0.90954029 | E21: =Sheet1!E21/Sheet1!$N18 -> 0.96440929 | F21: =Sheet1!F21/Sheet1!$N18 -> 1.1119624 | G21: =Sheet1!G21/Sheet1!$N18 -> 1.0182897 | H21: =Sheet1!H21/Sheet1!$N18 -> 1.0444884 | I21: =Sheet1!I21/Sheet1!$N18 -> 0.98393475 | J21: =Sheet1!J21/Sheet1!$N18 -> 1.0182897 | ... N21: =Sheet1!N21/Sheet1!$N18 -> 2.0108749
B22: H | C22: =Sheet1!C22/Sheet1!$N18 -> 1.2822541 | D22: =Sheet1!D22/Sheet1!$N18 -> 1.1089965 | E22: =Sheet1!E22/Sheet1!$N18 -> 1.0978744 | F22: =Sheet1!F22/Sheet1!$N18 -> 1.1243203 | G22: =Sheet1!G22/Sheet1!$N18 -> 1.0074147 | H22: =Sheet1!H22/Sheet1!$N18 -> 1.2244192 | I22: =Sheet1!I22/Sheet1!$N18 -> 1.0558576 | J22: =Sheet1!J22/Sheet1!$N18 -> 9.8961938 | ... N22: =Sheet1!N22/Sheet1!$N18 -> 1.9713297
A24: P3
B25: <> | C25: 1 | D25: 2 | E25: 3 | F25: 4 | G25: 5 | H25: 6 | I25: 7 | J25: 8 | K25: 9 | L25: 10 | M25: 11 | N25: 12
B26: A | C26: =Sheet1!C26/Sheet1!$N29 -> 2.3685015 | D26: =Sheet1!D26/Sheet1!$N29 -> 1.7379587 | E26: =Sheet1!E26/Sheet1!$N29 -> 1.3520642 | F26: =Sheet1!F26/Sheet1!$N29 -> 1.3738532 | G26: =Sheet1!G26/Sheet1!$N29 -> 1.0460627 | H26: =Sheet1!H26/Sheet1!$N29 -> 1.1093272 | I26: =Sheet1!I26/Sheet1!$N29 -> 0.96788991 | J26: =Sheet1!J26/Sheet1!$N29 -> 0.8858945 | ... N26: =Sheet1!N26/Sheet1!$N29 -> 1.0126147
B27: B | C27: =Sheet1!C27/Sheet1!$N29 -> 1.0808486 | D27: =Sheet1!D27/Sheet1!$N29 -> 1.1146789 | E27: =Sheet1!E27/Sheet1!$N29 -> 0.99770642 | F27: =Sheet1!F27/Sheet1!$N29 -> 0.98222477 | G27: =Sheet1!G27/Sheet1!$N29 -> 0.86983945 | H27: =Sheet1!H27/Sheet1!$N29 -> 0.72400612 | I27: =Sheet1!I27/Sheet1!$N29 -> 0.62672018 | J27: =Sheet1!J27/Sheet1!$N29 -> 0.60091743 | ... N27: =Sheet1!N27/Sheet1!$N29 -> 0.89659786
B28: C | C28: =Sheet1!C28/Sheet1!$N29 -> 0.89525994 | D28: =Sheet1!D28/Sheet1!$N29 -> 0.87710245 | E28: =Sheet1!E28/Sheet1!$N29 -> 0.87576453 | F28: =Sheet1!F28/Sheet1!$N29 -> 0.74560398 | G28: =Sheet1!G28/Sheet1!$N29 -> 0.62958716 | H28: =Sheet1!H28/Sheet1!$N29 -> 0.59327217 | I28: =Sheet1!I28/Sheet1!$N29 -> 0.60493119 | J28: =Sheet1!J28/Sheet1!$N29 -> 0.63149847 | ... N28: =Sheet1!N28/Sheet1!$N29 -> 0.95298165
B29: D | C29: =Sheet1!C29/Sheet1!$N29 -> 0.97801988 | D29: =Sheet1!D29/Sheet1!$N29 -> 0.97821101 | E29: =Sheet1!E29/Sheet1!$N29 -> 0.92201835 | F29: =Sheet1!F29/Sheet1!$N29 -> 0.80561927 | G29: =Sheet1!G29/Sheet1!$N29 -> 0.74961774 | H29: =Sheet1!H29/Sheet1!$N29 -> 0.75477829 | I29: =Sheet1!I29/Sheet1!$N29 -> 0.64468654 | J29: =Sheet1!J29/Sheet1!$N29 -> 0.71387615 | ... N29: =Sheet1!N29/Sheet1!$N29 -> 1
B30: E | C30: =Sheet1!C30/Sheet1!$N29 -> 1.0284786 | D30: =Sheet1!D30/Sheet1!$N29 -> 0.90921254 | E30: =Sheet1!E30/Sheet1!$N29 -> 0.90691896 | F30: =Sheet1!F30/Sheet1!$N29 -> 0.63302752 | G30: =Sheet1!G30/Sheet1!$N29 -> 0.66819572 | H30: =Sheet1!H30/Sheet1!$N29 -> 0.86582569 | I30: =Sheet1!I30/Sheet1!$N29 -> 0.64698012 | J30: =Sheet1!J30/Sheet1!$N29 -> 0.80504587 | ... N30: =Sheet1!N30/Sheet1!$N29 -> 2.0875382
B31: F | C31: =Sheet1!C31/Sheet1!$N29 -> 1.1974388 | D31: =Sheet1!D31/Sheet1!$N29 -> 0.98814985 | E31: =Sheet1!E31/Sheet1!$N29 -> 1.0474006 | F31: =Sheet1!F31/Sheet1!$N29 -> 0.75152905 | G31: =Sheet1!G31/Sheet1!$N29 -> 0.68157492 | H31: =Sheet1!H31/Sheet1!$N29 -> 0.79032875 | I31: =Sheet1!I31/Sheet1!$N29 -> 0.79434251 | J31: =Sheet1!J31/Sheet1!$N29 -> 0.9617737 | ... N31: =Sheet1!N31/Sheet1!$N29 -> 2.9353976
B32: G | C32: =Sheet1!C32/Sheet1!$N29 -> 1.1926606 | D32: =Sheet1!D32/Sheet1!$N29 -> 0.88512997 | E32: =Sheet1!E32/Sheet1!$N29 -> 0.95374618 | F32: =Sheet1!F32/Sheet1!$N29 -> 0.8191896 | G32: =Sheet1!G32/Sheet1!$N29 -> 0.85626911 | H32: =Sheet1!H32/Sheet1!$N29 -> 0.82243884 | I32: =Sheet1!I32/Sheet1!$N29 -> 0.77274465 | J32: =Sheet1!J32/Sheet1!$N29 -> 0.6941896 | ... N32: =Sheet1!N32/Sheet1!$N29 -> 2.1389526
B33: H | C33: =Sheet1!C33/Sheet1!$N29 -> 1.0038226 | D33: =Sheet1!D33/Sheet1!$N29 -> 1.0372706 | E33: =Sheet1!E33/Sheet1!$N29 -> 1.1314985 | F33: =Sheet1!F33/Sheet1!$N29 -> 0.944763 | G33: =Sheet1!G33/Sheet1!$N29 -> 0.88952599 | H33: =Sheet1!H33/Sheet1!$N29 -> 0.86295872 | I33: =Sheet1!I33/Sheet1!$N29 -> 0.79778287 | J33: =Sheet1!J33/Sheet1!$N29 -> 7.949159 | ... N33: =Sheet1!N33/Sheet1!$N29 -> 2.1441131
A35: P4
B36: <> | C36: 1 | D36: 2 | E36: 3 | F36: 4 | G36: 5 | H36: 6 | I36: 7 | J36: 8 | K36: 9 | L36: 10 | M36: 11 | N36: 12
B37: A | C37: =Sheet1!C37/Sheet1!$N40 -> 3.0259462 | D37: =Sheet1!D37/Sheet1!$N40 -> 1.487741 | E37: =Sheet1!E37/Sheet1!$N40 -> 1.2675553 | F37: =Sheet1!F37/Sheet1!$N40 -> 1.0478458 | G37: =Sheet1!G37/Sheet1!$N40 -> 1.092835 | H37: =Sheet1!H37/Sheet1!$N40 -> 1.0268984 | I37: =Sheet1!I37/Sheet1!$N40 -> 1.0199952 | J37: =Sheet1!J37/Sheet1!$N40 -> 1.1435373 | ... N37: =Sheet1!N37/Sheet1!$N40 -> 1.191145
B38: B | C38: =Sheet1!C38/Sheet1!$N40 -> 1.1847179 | D38: =Sheet1!D38/Sheet1!$N40 -> 1.1478219 | E38: =Sheet1!E38/Sheet1!$N40 -> 0.85574863 | F38: =Sheet1!F38/Sheet1!$N40 -> 0.76886456 | G38: =Sheet1!G38/Sheet1!$N40 -> 0.57771959 | H38: =Sheet1!H38/Sheet1!$N40 -> 0.66388955 | I38: =Sheet1!I38/Sheet1!$N40 -> 0.74529874 | J38: =Sheet1!J38/Sheet1!$N40 -> 0.69293025 | ... N38: =Sheet1!N38/Sheet1!$N40 -> 0.89954773
B39: C | C39: =Sheet1!C39/Sheet1!$N40 -> 1.2611283 | D39: =Sheet1!D39/Sheet1!$N40 -> 0.84265651 | E39: =Sheet1!E39/Sheet1!$N40 -> 0.90764104 | F39: =Sheet1!F39/Sheet1!$N40 -> 0.65151154 | G39: =Sheet1!G39/Sheet1!$N40 -> 0.61556772 | H39: =Sheet1!H39/Sheet1!$N40 -> 0.74006189 | I39: =Sheet1!I39/Sheet1!$N40 -> 0.53868127 | J39: =Sheet1!J39/Sheet1!$N40 -> 0.61556772 | ... N39: =Sheet1!N39/Sheet1!$N40 -> 0.97952868
B40: D | C40: =Sheet1!C40/Sheet1!$N40 -> 1.2670793 | D40: =Sheet1!D40/Sheet1!$N40 -> 0.95786717 | E40: =Sheet1!E40/Sheet1!$N40 -> 0.60628422 | F40: =Sheet1!F40/Sheet1!$N40 -> 0.84765532 | G40: =Sheet1!G40/Sheet1!$N40 -> 0.68935968 | H40: =Sheet1!H40/Sheet1!$N40 -> 0.58676506 | I40: =Sheet1!I40/Sheet1!$N40 -> 0.52749345 | J40: =Sheet1!J40/Sheet1!$N40 -> 0.69745299 | ... N40: =Sheet1!N40/Sheet1!$N40 -> 1
B41: E | C41: =Sheet1!C41/Sheet1!$N40 -> 1.2023328 | D41: =Sheet1!D41/Sheet1!$N40 -> 0.98381338 | E41: =Sheet1!E41/Sheet1!$N40 -> 0.70483218 | F41: =Sheet1!F41/Sheet1!$N40 -> 0.63603904 | G41: =Sheet1!G41/Sheet1!$N40 -> 0.84670317 | H41: =Sheet1!H41/Sheet1!$N40 -> 0.61651988 | I41: =Sheet1!I41/Sheet1!$N40 -> 0.70721257 | J41: =Sheet1!J41/Sheet1!$N40 -> 0.65912878 | ... N41: =Sheet1!N41/Sheet1!$N40 -> 2.043085
B42: F | C42: =Sheet1!C42/Sheet1!$N40 -> 1.2844561 | D42: =Sheet1!D42/Sheet1!$N40 -> 0.80457034 | E42: =Sheet1!E42/Sheet1!$N40 -> 0.71197334 | F42: =Sheet1!F42/Sheet1!$N40 -> 0.75743871 | G42: =Sheet1!G42/Sheet1!$N40 -> 0.8314687 | H42: =Sheet1!H42/Sheet1!$N40 -> 0.73125446 | I42: =Sheet1!I42/Sheet1!$N40 -> 0.77386337 | J42: =Sheet1!J42/Sheet1!$N40 -> 0.88074268 | ... N42: =Sheet1!N42/Sheet1!$N40 -> 1.9350155
B43: G | C43: =Sheet1!C43/Sheet1!$N40 -> 1.3442038 | D43: =Sheet1!D43/Sheet1!$N40 -> 0.87050702 | E43: =Sheet1!E43/Sheet1!$N40 -> 0.8450369 | F43: =Sheet1!F43/Sheet1!$N40 -> 1.0590336 | G43: =Sheet1!G43/Sheet1!$N40 -> 0.69150202 | H43: =Sheet1!H43/Sheet1!$N40 -> 0.73482504 | I43: =Sheet1!I43/Sheet1!$N40 -> 0.75339205 | J43: =Sheet1!J43/Sheet1!$N40 -> 0.71602 | ... N43: =Sheet1!N43/Sheet1!$N40 -> 1.3313497
...

Sheet final
B1: original signal | C1: fold change to m002 benchmark
A2: m176 UTR | B2: 1.164125 | C2: 2.4929422
A3: A2 | B3: 0.71605 | C3: 1.5123282
A4: A3 | B4: 0.621275 | C4: 1.3131475
A5: A4 | B5: 0.59265 | C5: 1.2531207
A6: A5 | B6: 0.50225 | C6: 1.0677538
A7: A6 | B7: 0.489675 | C7: 1.0380004
A8: A7 | B8: 0.494425 | C8: 1.0499248
A9: A8 | B9: 0.49315 | C9: 1.0582594
A10: A9 | B10: 0.5135 | C10: 1.0947837
A11: A10 | B11: 0.49315 | C11: 1.0531301
A12: A11 | B12: 0.468375 | C12: 0.99484389
A13: A12 | B13: 0.55865 | C13: 1.1896241
... A97: H12 | B97: 1.00615 | C97: 2.1188005

Sheet Sheet4
B1: original signal | C1: fold change to m002 benchmark
A2: A1 | B2: 1.164125 | C2: 2.4929422 | F2: m176 UTR
A3: A2 | B3: 0.71605 | C3: 1.5123282
A4: A3 | B4: 0.621275 | C4: 1.3131475
A5: A4 | B5: 0.59265 | C5: 1.2531207
A6: A5 | B6: 0.50225 | C6: 1.0677538
A7: A6 | B7: 0.489675 | C7: 1.0380004
A8: A7 | B8: 0.494425 | C8: 1.0499248
A9: A8 | B9: 0.49315 | C9: 1.0582594
A10: A9 | B10: 0.5135 | C10: 1.0947837
A11: A10 | B11: 0.49315 | C11: 1.0531301
A12: A11 | B12: 0.468375 | C12: 0.99484389
A13: A12 | B13: 0.55865 | C13: 1.1896241
A14: B1 | B14: 0.515525 | C14: 1.0982074
... A48: D11 | B48: 0.39415 | C48: 0.82284594
A49: D12 | B49: 0.4735 | C49: 1 | F49: m002 UTR, benchmark
A50: E1 | B50: 0.5025 | C50: 1.0743272
A51: E2 | B51: 0.4596 | C51: 0.96691367
A52: E3 | B52: 0.395675 | C52: 0.83007384
A53: E4 | B53: 0.336 | C53: 0.70914046
A54: E5 | B54: 0.370875 | C54: 0.78694746
A55: E6 | B55: 0.3617 | C55: 0.75370562
A56: E7 | B56: 0.3715 | C56: 0.78086413
A57: E8 | B57: 0.422075 | C57: 0.88761667
A58: E9 | B58: 0.380275 | C58: 0.80430237
A59: E10 | B59: 0.409425 | C59: 0.86698089
A60: E11 | B60: 0.394875 | C60: 0.82680333
A61: E12 | B61: 1.10195 | C61: 2.3561624
... A92: H7 | B92: 0.449125 | C92: 0.94815858
A93: H8 | B93: 4.0735 | C93: 8.7371174 | F93: m801
A94: H9 | B94: 0.43335 | C94: 0.92012052
A95: H10 | B95: 0.4268 | C95: 0.89471243
A96: H11 | B96: 0.48965 | C96: 1.0426997
A97: H12 | B97: 1.00615 | C97: 2.1188005
